<?xml version="1.0" ?>
<robot xmlns:xacro="http://www.ros.org/wiki/xacro" name="firefighter">
    <xacro:property name="width" value=".2" />
    <link name="g_base">
        <visual>
            <geometry>
                <mesh filename="package://jetcobot_description/urdf/mycobot_280_m5/G_base.dae" />
            </geometry>
            <origin xyz="0.0 0 -0.03" rpy="0 0 1.5708" />
        </visual>
        <collision>
            <geometry>
                <mesh filename="package://jetcobot_description/urdf/mycobot_280_m5/G_base.dae" />
            </geometry>
            <origin xyz="0.0 0 -0.03" rpy="0 0 1.5708" />
        </collision>
        <inertial>
            <mass value="0.1" />
            <origin xyz="0 0 0" rpy="0 0 0" />
            <inertia ixx="0.03" iyy="0.03" izz="0.03" ixy="0.0" ixz="0.0" iyz="0.0" />
        </inertial>
    </link>
    <link name="link1">
        <visual>
            <geometry>
                <!--- 0.0 0 -0.04  1.5708 3.14159-->
                <mesh filename="package://jetcobot_description/urdf/mycobot_280_m5/joint1.dae" />
            </geometry>
            <origin xyz="0.0 0 0 " rpy=" 0 0 -1.5708" />
        </visual>
        <collision>
            <geometry>
                <!--- 0.0 0 -0.04  1.5708 3.14159-->
                <mesh filename="package://jetcobot_description/urdf/mycobot_280_m5/joint1.dae" />
            </geometry>
            <origin xyz="0.0 0 0 " rpy=" 0 0 -1.5708" />
        </collision>
        <inertial>
            <mass value="0.1" />
            <origin xyz="0 0 0" rpy="0 0 0" />
            <inertia ixx="0.03" iyy="0.03" izz="0.03" ixy="0.0" ixz="0.0" iyz="0.0" />
        </inertial>
    </link>
    <link name="link2">
        <visual>
            <geometry>
                <mesh filename="package://jetcobot_description/urdf/mycobot_280_m5/joint2.dae" />
            </geometry>
            <origin xyz="0.0 0 -0.06096 " rpy=" 0 0 -1.5708" />
        </visual>
        <collision>
            <geometry>
                <mesh filename="package://jetcobot_description/urdf/mycobot_280_m5/joint2.dae" />
            </geometry>
            <origin xyz="0.0 0 -0.06096 " rpy=" 0 0 -1.5708" />
        </collision>
        <inertial>
            <mass value="0.1" />
            <origin xyz="0 0 0" rpy="0 0 0" />
            <inertia ixx="0.03" iyy="0.03" izz="0.03" ixy="0.0" ixz="0.0" iyz="0.0" />
        </inertial>
    </link>
    <link name="link3">
        <visual>
            <geometry>
                <mesh filename="package://jetcobot_description/urdf/mycobot_280_m5/joint3.dae" />
            </geometry>
            <origin xyz="0.0 0 0.03256 " rpy=" 0 -1.5708 0" />
        </visual>
        <collision>
            <geometry>
                <mesh filename="package://jetcobot_description/urdf/mycobot_280_m5/joint3.dae" />
            </geometry>
            <origin xyz="0.0 0 0.03256 " rpy=" 0 -1.5708 0" />
        </collision>
        <inertial>
            <mass value="0.1" />
            <origin xyz="0 0 0" rpy="0 0 0" />
            <inertia ixx="0.03" iyy="0.03" izz="0.03" ixy="0.0" ixz="0.0" iyz="0.0" />
        </inertial>
    </link>
    <link name="link4">
        <visual>
            <geometry>
                <!--- 0.0 0 -0.04 -->
                <mesh filename="package://jetcobot_description/urdf/mycobot_280_m5/joint4.dae" />
            </geometry>
            <origin xyz="0.0 0 0.03056 " rpy=" 0 -1.5708 0" />
        </visual>
        <collision>
            <geometry>
                <!--- 0.0 0 -0.04 -->
                <mesh filename="package://jetcobot_description/urdf/mycobot_280_m5/joint4.dae" />
            </geometry>
            <origin xyz="0.0 0 0.03056 " rpy=" 0 -1.5708 0" />
        </collision>
        <inertial>
            <mass value="0.1" />
            <origin xyz="0 0 0" rpy="0 0 0" />
            <inertia ixx="0.03" iyy="0.03" izz="0.03" ixy="0.0" ixz="0.0" iyz="0.0" />
        </inertial>
    </link>
    <link name="link5">
        <visual>
            <geometry>
                <!--- 0.0 0 -0.04 -->
                <mesh filename="package://jetcobot_description/urdf/mycobot_280_m5/joint5.dae" />
            </geometry>
            <origin xyz="0.0 0 -0.03356 " rpy=" -1.5708 0 0" />
        </visual>
        <collision>
            <geometry>
                <!--- 0.0 0 -0.04 -->
                <mesh filename="package://jetcobot_description/urdf/mycobot_280_m5/joint5.dae" />
            </geometry>
            <origin xyz="0.0 0 -0.03356 " rpy=" -1.5708 0 0" />
        </collision>
        <inertial>
            <mass value="0.1" />
            <origin xyz="0 0 0" rpy="0 0 0" />
            <inertia ixx="0.03" iyy="0.03" izz="0.03" ixy="0.0" ixz="0.0" iyz="0.0" />
        </inertial>
    </link>
    <link name="link6">
        <visual>
            <geometry>
                <!--- 0.0 0 -0.04 -->
                <mesh filename="package://jetcobot_description/urdf/mycobot_280_m5/joint6.dae" />
            </geometry>
            <origin xyz="0 0.00 -0.038 " rpy=" 0 0 0" />
        </visual>
        <collision>
            <geometry>
                <!--- 0.0 0 -0.04 -->
                <mesh filename="package://jetcobot_description/urdf/mycobot_280_m5/joint6.dae" />
            </geometry>
            <origin xyz="0 0.00 -0.038 " rpy=" 0 0 0" />
        </collision>
        <inertial>
            <mass value="0.1" />
            <origin xyz="0 0 0" rpy="0 0 0" />
            <inertia ixx="0.03" iyy="0.03" izz="0.03" ixy="0.0" ixz="0.0" iyz="0.0" />
        </inertial>
    </link>
    <link name="link6_flange">
        <visual>
            <geometry>
                <!--- 0.0 0 -0.04 -->
                <mesh filename="package://jetcobot_description/urdf/mycobot_280_m5/joint7.dae" />
            </geometry>
            <origin xyz="0.0 0 -0.012 " rpy=" 0 0 0" />
        </visual>
        <collision>
            <geometry>
                <!--- 0.0 0 -0.04 -->
                <mesh filename="package://jetcobot_description/urdf/mycobot_280_m5/joint7.dae" />
            </geometry>
            <origin xyz="0.0 0 -0.012 " rpy=" 0 0 0" />
        </collision>
        <inertial>
            <mass value="0.1" />
            <origin xyz="0 0 0" rpy="0 0 0" />
            <inertia ixx="0.03" iyy="0.03" izz="0.03" ixy="0.0" ixz="0.0" iyz="0.0" />
        </inertial>
    </link>
    <link name="gripper_base">
        <visual>
            <geometry>
                <!--- 0.0 0 -0.04 -->
                <mesh filename="package://jetcobot_description/urdf/mycobot_280_m5/gripper_base.dae" />
            </geometry>
            <origin xyz="0.0 0 -0.012 " rpy=" 0 0 0" />
        </visual>
        <collision>
            <geometry>
                <!--- 0.0 0 -0.04 -->
                <box size="0.05 0.04 0.05"/>
                <!-- <mesh filename="package://jetcobot_description/urdf/mycobot_280_m5/gripper_base.dae" /> -->
            </geometry>
            <origin xyz="0.0 0 0.01 " rpy=" 0 0 0" />
        </collision>
        <inertial>
            <mass value="0.1" />
            <origin xyz="0 0 0" rpy="0 0 0" />
            <inertia ixx="0.03" iyy="0.03" izz="0.03" ixy="0.0" ixz="0.0" iyz="0.0" />
        </inertial>
    </link>
    <link name="gripper_left1">
        <visual>
            <geometry>
                <!--- 0.0 0 -0.04 -->
                <mesh filename="package://jetcobot_description/urdf/mycobot_280_m5/gripper_left1.dae" />
            </geometry>
            <origin xyz="0.039 -0.0133 -0.012 " rpy=" 0 0 0" />
            <!-- <origin xyz = "0.0 0 -0.012 " rpy = " 0 0 0"/> -->
        </visual>
        <collision>
            <geometry>
                <box size="0.015 0.06 0.02"/>
                <!-- <mesh filename="package://jetcobot_description/urdf/mycobot_280_m5/gripper_left1.dae" /> -->
            </geometry>
            <origin xyz="0.01 0.03 -0.008 " rpy=" 0 0 0" />
        </collision>
        <inertial>
            <mass value="0.1" />
            <origin xyz="0 0 0" rpy="0 0 0" />
            <inertia ixx="0.03" iyy="0.03" izz="0.03" ixy="0.0" ixz="0.0" iyz="0.0" />
        </inertial>
    </link>
    <link name="gripper_left2">
        <visual>
            <geometry>
                <mesh filename="package://jetcobot_description/urdf/mycobot_280_m5/gripper_left2.dae" />
            </geometry>
            <origin xyz="0.005 -0.0195 -0.012 " rpy=" 0 0 0" />
        </visual>
        <collision>
            <geometry>
                <mesh filename="package://jetcobot_description/urdf/mycobot_280_m5/gripper_left2.dae" />
            </geometry>
            <origin xyz="0.005 -0.0195 -0.012 " rpy=" 0 0 0" />
        </collision>
        <inertial>
            <mass value="0.1" />
            <origin xyz="0 0 0" rpy="0 0 0" />
            <inertia ixx="0.03" iyy="0.03" izz="0.03" ixy="0.0" ixz="0.0" iyz="0.0" />
        </inertial>
    </link>
    <link name="gripper_left3">
        <visual>
            <geometry>
                <mesh filename="package://jetcobot_description/urdf/mycobot_280_m5/gripper_left3.dae" />
            </geometry>
            <origin xyz="0.012 0.0025 -0.012 " rpy=" 0 0 0" />
        </visual>
        <collision>
            <geometry>
                <mesh filename="package://jetcobot_description/urdf/mycobot_280_m5/gripper_left3.dae" />
            </geometry>
            <origin xyz="0.012 0.0025 -0.012 " rpy=" 0 0 0" />
        </collision>
        <inertial>
            <mass value="0.1" />
            <origin xyz="0 0 0" rpy="0 0 0" />
            <inertia ixx="0.03" iyy="0.03" izz="0.03" ixy="0.0" ixz="0.0" iyz="0.0" />
        </inertial>
    </link>
    <link name="gripper_right1">
        <visual>
            <geometry>
                <mesh filename="package://jetcobot_description/urdf/mycobot_280_m5/gripper_right1.dae" />
            </geometry>
            <origin xyz="-0.039 -0.0133 -0.012 " rpy=" 0 0 0" />
        </visual>
        <collision>
            <geometry>
                <box size="0.015 0.06 0.02"/>
                <!-- <mesh filename="package://jetcobot_description/urdf/mycobot_280_m5/gripper_right1.dae" /> -->
            </geometry>
            <origin xyz="-0.01 0.03 -0.008 " rpy=" 0 0 0" />
        </collision>
        <inertial>
            <mass value="0.1" />
            <origin xyz="0 0 0" rpy="0 0 0" />
            <inertia ixx="0.03" iyy="0.03" izz="0.03" ixy="0.0" ixz="0.0" iyz="0.0" />
        </inertial>
    </link>
    <link name="gripper_right2">
        <visual>
            <geometry>
                <mesh filename="package://jetcobot_description/urdf/mycobot_280_m5/gripper_right2.dae" />
            </geometry>
            <origin xyz="-0.005 -0.0195 -0.012 " rpy=" 0 0 0" />
        </visual>
        <collision>
            <geometry>
                <mesh filename="package://jetcobot_description/urdf/mycobot_280_m5/gripper_right2.dae" />
            </geometry>
            <origin xyz="-0.005 -0.0195 -0.012 " rpy=" 0 0 0" />
        </collision>
        <inertial>
            <mass value="0.1" />
            <origin xyz="0 0 0" rpy="0 0 0" />
            <inertia ixx="0.03" iyy="0.03" izz="0.03" ixy="0.0" ixz="0.0" iyz="0.0" />
        </inertial>
    </link>
    <link name="gripper_right3">
        <visual>
            <geometry>
                <mesh filename="package://jetcobot_description/urdf/mycobot_280_m5/gripper_right3.dae" />
            </geometry>
            <origin xyz="-0.012 0.0025 -0.012 " rpy=" 0 0 0" />
        </visual>
        <collision>
            <geometry>
                <mesh filename="package://jetcobot_description/urdf/mycobot_280_m5/gripper_right3.dae" />
            </geometry>
            <origin xyz="-0.012 0.0025 -0.012 " rpy=" 0 0 0" />
        </collision>
        <inertial>
            <mass value="0.1" />
            <origin xyz="0 0 0" rpy="0 0 0" />
            <inertia ixx="0.03" iyy="0.03" izz="0.03" ixy="0.0" ixz="0.0" iyz="0.0" />
        </inertial>
    </link>
    <link name="jetcocam">
        <visual>
            <geometry>
                <box size="0.04 0.05 0.015"/>
            </geometry>
            <origin xyz="0 0.016 0.005" rpy="0 0 0"/>
        </visual>
        <collision>
            <geometry>
                <box size="0.04 0.05 0.015"/>
            </geometry>
            <origin xyz="0 0.016 0.005" rpy="0 0 0"/>
        </collision>
        <inertial>
            <mass value="0.1"/>
            <origin xyz="0 0 0" rpy="0 0 0"/>
            <inertia ixx="0.03" iyy="0.03" izz="0.03" ixy="0.0" ixz="0.0" iyz="0.0"/>
        </inertial>
    </link>
    <link name="TCP">
        <visual>
            <geometry>
                <box size="0.01 0.01 0.01"/>
            </geometry>
            <origin xyz="0 0 0" rpy="0 0 0"/>
        </visual>
    </link>
    <joint name="g_base_to_link1" type="fixed">
        <axis xyz="0 0 0" />
        <limit effort="1000.0" lower="-3.14" upper="3.14159" velocity="0" />
        <parent link="g_base" />
        <child link="link1" />
        <origin xyz="0 0 0" rpy="0 0 0" />
    </joint>
    <joint name="link2_to_link1" type="revolute">
        <axis xyz="0 0 1" />
        <limit effort="1000.0" lower="-2.9321" upper="2.9321" velocity="0" />
        <parent link="link1" />
        <child link="link2" />
        <origin xyz="0 0 0.13156" rpy="0 0 0" />
    </joint>
    <joint name="link3_to_link2" type="revolute">
        <axis xyz="0 0 1" />
        <limit effort="1000.0" lower="-2.3561" upper="2.3561" velocity="0" />
        <parent link="link2" />
        <child link="link3" />
        <origin xyz="0 0  0" rpy="0 1.5708 -1.5708" />
    </joint>
    <joint name="link4_to_link3" type="revolute">
        <axis xyz=" 0 0 1" />
        <limit effort="1000.0" lower="-2.6179" upper="2.6179" velocity="0" />
        <parent link="link3" />
        <child link="link4" />
        <origin xyz="  -0.1104 0 0   " rpy="0 0 0" />
    </joint>
    <joint name="link5_to_link4" type="revolute">
        <axis xyz=" 0 0 1" />
        <limit effort="1000.0" lower="-2.5307" upper="2.5307" velocity="0" />
        <parent link="link4" />
        <child link="link5" />
        <origin xyz="-0.096 0 0.06462" rpy="0 0 -1.5708" />
    </joint>
    <joint name="link6_to_link5" type="revolute">
        <axis xyz="0 0 1" />
        <limit effort="1000.0" lower="-2.879793" upper="2.879793" velocity="0" />
        <parent link="link5" />
        <child link="link6" />
        <origin xyz="0 -0.07318 0" rpy="1.5708 -1.5708 0" />
    </joint>
    <joint name="link6output_to_link6" type="revolute">
        <axis xyz="0 0 1" />
        <limit effort="1000.0" lower="-3.14" upper="3.14" velocity="0" />
        <parent link="link6" />
        <child link="link6_flange" />
        <origin xyz="0 0.0456 0" rpy="-1.5708 0 0" />
    </joint>
    <joint name="link6output_to_gripper_base" type="fixed">
        <!-- <axis xyz="0 0 1"/>
    <limit effort = "1000.0" lower = "-3.14" upper = "3.14159" velocity = "0"/> -->
        <parent link="link6_flange" />
        <child link="gripper_base" />
        <origin xyz="0 0 0.034" rpy="1.579 0 -2.3562" />
    </joint>
    <joint name="gripper_base_to_jetcocam" type="fixed">
        <parent link="gripper_base"/>
        <child link="jetcocam"/>
        <origin xyz="0 -0.01 -0.048" rpy="-1.5708 3.1416 0"/>
    </joint>
    <joint name="gripper_base_to_TCP" type="fixed">
        <parent link="gripper_base"/>
        <child link="TCP"/>
        <origin xyz="0 0.07 0" rpy="-1.5708 3.1416 0"/>
    </joint>
    <joint name="gripper_controller" type="revolute">
        <axis xyz="0 0 1" />
        <limit effort="1000.0" lower="-0.78" upper="0.15" velocity="0" />
        <parent link="gripper_base" />
        <child link="gripper_left3" />
        <origin xyz="-0.012 0.005 0" rpy="0 0 0" />
    </joint>
    <joint name="gripper_base_to_gripper_left2" type="revolute">
        <axis xyz="0 0 1" />
        <limit effort="1000.0" lower="-0.8" upper="0.5" velocity="0" />
        <parent link="gripper_base" />
        <child link="gripper_left2" />
        <origin xyz="-0.005 0.027 0" rpy="0 0 0" />
        <mimic joint="gripper_controller" multiplier="1.0" offset="0" />
    </joint>
    <joint name="gripper_left3_to_gripper_left1" type="revolute">
        <axis xyz="0 0 1" />
        <limit effort="1000.0" lower="-0.5" upper="0.5" velocity="0" />
        <parent link="gripper_left3" />
        <child link="gripper_left1" />
        <origin xyz="-0.027 0.016 0" rpy="0 0 0" />
        <mimic joint="gripper_controller" multiplier="-1.0" offset="0" />
    </joint>
    <joint name="gripper_base_to_gripper_right3" type="revolute">
        <axis xyz="0 0 1" />
        <limit effort="1000.0" lower="-0.15" upper="0.7" velocity="0" />
        <parent link="gripper_base" />
        <child link="gripper_right3" />
        <origin xyz="0.012 0.005 0" rpy="0 0 0" />
        <mimic joint="gripper_controller" multiplier="-1.0" offset="0" />
    </joint>
    <joint name="gripper_base_to_gripper_right2" type="revolute">
        <axis xyz="0 0 1" />
        <limit effort="1000.0" lower="-0.5" upper="0.8" velocity="0" />
        <parent link="gripper_base" />
        <child link="gripper_right2" />
        <origin xyz="0.005 0.027 0" rpy="0 0 0" />
        <mimic joint="gripper_controller" multiplier="-1.0" offset="0" />
    </joint>
    <joint name="gripper_right3_to_gripper_right1" type="revolute">
        <axis xyz="0 0 1" />
        <limit effort="1000.0" lower="-0.5" upper="0.5" velocity="0" />
        <parent link="gripper_right3" />
        <child link="gripper_right1" />
        <origin xyz="0.027 0.016 0" rpy="0 0 0" />
        <mimic joint="gripper_controller" multiplier="1.0" offset="0" />
    </joint>
    <transmission name="trans_link2_to_link1">
        <type>transmission_interface/SimpleTransmission</type>
        <joint name="link2_to_link1">
            <hardwareInterface>hardware_interface/EffortJointInterface</hardwareInterface>
        </joint>
        <actuator name="link2_to_link1_motor">
            <hardwareInterface>hardware_interface/EffortJointInterface</hardwareInterface>
            <mechanicalReduction>1</mechanicalReduction>
        </actuator>
    </transmission>
    <transmission name="trans_link3_to_link2">
        <type>transmission_interface/SimpleTransmission</type>
        <joint name="link3_to_link2">
            <hardwareInterface>hardware_interface/EffortJointInterface</hardwareInterface>
        </joint>
        <actuator name="link3_to_link2_motor">
            <hardwareInterface>hardware_interface/EffortJointInterface</hardwareInterface>
            <mechanicalReduction>1</mechanicalReduction>
        </actuator>
    </transmission>
    <transmission name="trans_link4_to_link3">
        <type>transmission_interface/SimpleTransmission</type>
        <joint name="link4_to_link3">
            <hardwareInterface>hardware_interface/EffortJointInterface</hardwareInterface>
        </joint>
        <actuator name="link4_to_link3_motor">
            <hardwareInterface>hardware_interface/EffortJointInterface</hardwareInterface>
            <mechanicalReduction>1</mechanicalReduction>
        </actuator>
    </transmission>
    <transmission name="trans_link5_to_link4">
        <type>transmission_interface/SimpleTransmission</type>
        <joint name="link5_to_link4">
            <hardwareInterface>hardware_interface/EffortJointInterface</hardwareInterface>
        </joint>
        <actuator name="link5_to_link4_motor">
            <hardwareInterface>hardware_interface/EffortJointInterface</hardwareInterface>
            <mechanicalReduction>1</mechanicalReduction>
        </actuator>
    </transmission>
    <transmission name="trans_link6_to_link5">
        <type>transmission_interface/SimpleTransmission</type>
        <joint name="link6_to_link5">
            <hardwareInterface>hardware_interface/EffortJointInterface</hardwareInterface>
        </joint>
        <actuator name="link6_to_link5_motor">
            <hardwareInterface>hardware_interface/EffortJointInterface</hardwareInterface>
            <mechanicalReduction>1</mechanicalReduction>
        </actuator>
    </transmission>
    <transmission name="trans_link6output_to_link6">
        <type>transmission_interface/SimpleTransmission</type>
        <joint name="link6output_to_link6">
            <hardwareInterface>hardware_interface/EffortJointInterface</hardwareInterface>
        </joint>
        <actuator name="link6output_to_link6_motor">
            <hardwareInterface>hardware_interface/EffortJointInterface</hardwareInterface>
            <mechanicalReduction>1</mechanicalReduction>
        </actuator>
    </transmission>
    <transmission name="trans_gripper_controller">
        <type>transmission_interface/SimpleTransmission</type>
        <joint name="gripper_controller">
            <hardwareInterface>hardware_interface/EffortJointInterface</hardwareInterface>
        </joint>
        <actuator name="gripper_controller_motor">
            <hardwareInterface>hardware_interface/EffortJointInterface</hardwareInterface>
            <mechanicalReduction>1</mechanicalReduction>
        </actuator>
    </transmission>
    <transmission name="trans_gripper_base_to_gripper_left2">
        <type>transmission_interface/SimpleTransmission</type>
        <joint name="gripper_base_to_gripper_left2">
            <hardwareInterface>hardware_interface/EffortJointInterface</hardwareInterface>
        </joint>
        <actuator name="gripper_base_to_gripper_left2_motor">
            <hardwareInterface>hardware_interface/EffortJointInterface</hardwareInterface>
            <mechanicalReduction>1</mechanicalReduction>
        </actuator>
    </transmission>
    <transmission name="trans_gripper_left3_to_gripper_left1">
        <type>transmission_interface/SimpleTransmission</type>
        <joint name="gripper_left3_to_gripper_left1">
            <hardwareInterface>hardware_interface/EffortJointInterface</hardwareInterface>
        </joint>
        <actuator name="gripper_left3_to_gripper_left1_motor">
            <hardwareInterface>hardware_interface/EffortJointInterface</hardwareInterface>
            <mechanicalReduction>1</mechanicalReduction>
        </actuator>
    </transmission>
    <transmission name="trans_gripper_base_to_gripper_right3">
        <type>transmission_interface/SimpleTransmission</type>
        <joint name="gripper_base_to_gripper_right3">
            <hardwareInterface>hardware_interface/EffortJointInterface</hardwareInterface>
        </joint>
        <actuator name="gripper_base_to_gripper_right3_motor">
            <hardwareInterface>hardware_interface/EffortJointInterface</hardwareInterface>
            <mechanicalReduction>1</mechanicalReduction>
        </actuator>
    </transmission>
    <transmission name="trans_gripper_base_to_gripper_right2">
        <type>transmission_interface/SimpleTransmission</type>
        <joint name="gripper_base_to_gripper_right2">
            <hardwareInterface>hardware_interface/EffortJointInterface</hardwareInterface>
        </joint>
        <actuator name="gripper_base_to_gripper_right2_motor">
            <hardwareInterface>hardware_interface/EffortJointInterface</hardwareInterface>
            <mechanicalReduction>1</mechanicalReduction>
        </actuator>
    </transmission>
    <transmission name="trans_gripper_right3_to_gripper_right1">
        <type>transmission_interface/SimpleTransmission</type>
        <joint name="gripper_right3_to_gripper_right1">
            <hardwareInterface>hardware_interface/EffortJointInterface</hardwareInterface>
        </joint>
        <actuator name="gripper_right3_to_gripper_right1_motor">
            <hardwareInterface>hardware_interface/EffortJointInterface</hardwareInterface>
            <mechanicalReduction>1</mechanicalReduction>
        </actuator>
    </transmission>
    <gazebo>
        <plugin name="gazebo_ros_control">
            <robotNamespace>/</robotNamespace>
        </plugin>
    </gazebo>
</robot>

